---
title: '协程关键字 - coroutineScope vs supervisorScope'
author: litao
date: 2023-05-11 21:37:00 +0800
categories: [Kotlin,Course,Coroutine]
tags: [Course,Kotlin,Coroutine]
---

## 一. coroutineScope vs supervisorScope

在 Kotlin 协程中，`coroutineScope` 和 `supervisorScope` 都用于创建协程作用域，但它们在错误处理和子协程的生命周期管理方面有显著的区别

### 1. coroutineScope

#### 特点

- **层级结构**: `coroutineScope` 会创建一个新的协程作用域，其中启动的所有协程都是这个作用域的子协程。
- **错误传播**: `coroutineScope` 中的任何一个子协程失败，整个作用域都会被取消，其他子协程也会被取消。

#### 使用场景

- **整体失败时需要取消所有协程**: 当一个子协程失败时，你希望取消该作用域中的所有其他子协程。
- **需要等待所有子协程完成**: `coroutineScope` 挂起，直到作用域内的所有子协程完成。

#### 示例

```kotlin
import kotlinx.coroutines.*

fun main() = runBlocking {
    try {
        coroutineScope {
            launch {
                delay(200L)
                println("Task 1 completed")
            }
            launch {
                delay(100L)
                throw RuntimeException("Task 2 failed")
            }
            launch {
                delay(300L)
                println("Task 3 completed")
            }
        }
    } catch (e: Exception) {
        println("Coroutine scope failed with exception: ${e.message}")
    }
}
```

输出结果：

```shell
Task 1 completed
Coroutine scope failed with exception: Task 2 failed
```

在这个示例中，`Task 2` 失败后，整个 `coroutineScope` 被取消，`Task 3` 没有完成。



### 2. supervisorScope

#### 特点

- **层级结构**: `supervisorScope` 也会创建一个新的协程作用域，但它的错误处理方式不同。
- **错误隔离**: `supervisorScope` 中的子协程独立运行，一个子协程的失败不会影响其他子协程。失败的子协程会取消，但其他子协程继续运行。

#### 使用场景

- **需要容忍部分协程失败**: 当你希望某些子协程失败时，不影响其他子协程继续运行。
- **局部失败而非全局失败**: 用于需要局部失败处理而非全局取消的场景。

#### 示例

```kotlin
import kotlinx.coroutines.*

fun main() = runBlocking {
    supervisorScope {
        val job1 = launch {
            delay(200L)
            println("Task 1 completed")
        }
        val job2 = launch {
            delay(100L)
            throw RuntimeException("Task 2 failed")
        }
        val job3 = launch {
            delay(300L)
            println("Task 3 completed")
        }

        try {
            job2.join()
        } catch (e: Exception) {
            println("Job 2 failed with exception: ${e.message}")
        }
    }
    println("Supervisor scope is over")
}
```

输出结果：

```
Task 1 completed
Job 2 failed with exception: Task 2 failed
Task 3 completed
Supervisor scope is over
```

尽管 `Task 2` 失败了，但 `Task 1` 和 `Task 3` 继续运行并完成

